<?xml version="1.0" ?>
<!-- =================================================================================== -->
<!-- |    This document was autogenerated by xacro from pipettingrobot_C5.urdf.xacro   | -->
<!-- |    EDITING THIS FILE BY HAND IS NOT RECOMMENDED                                 | -->
<!-- =================================================================================== -->
<robot name="pipetting_robot">
  <dh_type type="modified"/>
  <safety_para singularity_consistent="0.02 0.01 10 0.2 0.045 10"/>
  <friction_coeff value="0.65"/>
  <!-- 定义支架链接，质量 25 kg -->
  <link name="support_link">
    <inertial>
      <!-- 圆柱体惯性： Ixx=Iyy=1/12·m·(3r²+h²)，Izz=1/2·m·r² -->
      <origin rpy="0 0 0" xyz="0 0 0.4725"/>
      <mass value="25"/>
      <inertia ixx="1.8761" ixy="0" ixz="0" iyy="1.8761" iyz="0" izz="0.03125"/>
    </inertial>
    <visual>
      <origin rpy="0 0 0" xyz="0 0 0.4725"/>
      <geometry>
        <cylinder length="0.945" radius="0.1"/>
      </geometry>
      <material name="Grey">
        <color rgba="0.6 0.6 0.6 1"/>
      </material>
    </visual>
    <collision>
      <origin rpy="0 0 0" xyz="0 0 0.4725"/>
      <geometry>
        <cylinder length="0.945" radius="0.10"/>
      </geometry>
    </collision>
  </link>
  <!-- support_link 到 base_link 的固定关节 -->
  <joint name="support_to_base" type="fixed">
    <parent link="support_link"/>
    <child link="base_link"/>
    <origin rpy="0 0 0" xyz="0.0 0.0 0.945"/>
  </joint>
  <link name="base_link">
    <inertial>
      <origin rpy="0 0 0" xyz="0.000129 0.001249 0.016678"/>
      <mass value="1.53902"/>
      <inertia ixx="0.003278" ixy="-0.000001" ixz="-0.000001" iyy="0.003017" iyz="-0.000048" izz="0.005841"/>
    </inertial>
    <visual>
      <origin rpy="0 0 0" xyz="0 0 0"/>
      <geometry>
        <mesh filename="/home/robot/pipetbot_ros2_ws/install/pipettingrobot_sim/share/pipettingrobot_sim/meshes/pipetting_robot/visual/link0.DAE"/>
      </geometry>
      <material name="">
        <color rgba="1 1 1 1"/>
      </material>
    </visual>
    <collision name="base_collision">
      <origin rpy="0 0 0" xyz="0 0 0"/>
      <geometry>
        <mesh filename="/home/robot/pipetbot_ros2_ws/install/pipettingrobot_sim/share/pipettingrobot_sim/meshes/pipetting_robot/collision/link0.STL"/>
      </geometry>
    </collision>
  </link>
  <link name="shoulder_Link">
    <inertial>
      <origin rpy="0 0 0" xyz="-0.00001 0.001807 -0.013854"/>
      <mass value="4.848581"/>
      <inertia ixx="0.011842" ixy="0" ixz="0.000004" iyy="0.0118" iyz="-0.000103" izz="0.008103"/>
    </inertial>
    <visual>
      <origin rpy="0 0 0" xyz="0 0 0"/>
      <geometry>
        <mesh filename="/home/robot/pipetbot_ros2_ws/install/pipettingrobot_sim/share/pipettingrobot_sim/meshes/pipetting_robot/visual/link1.DAE"/>
      </geometry>
      <material name="">
        <color rgba="1 1 1 1"/>
      </material>
    </visual>
    <collision name="shoulder_collision">
      <origin rpy="0 0 0" xyz="0 0 0"/>
      <geometry>
        <mesh filename="/home/robot/pipetbot_ros2_ws/install/pipettingrobot_sim/share/pipettingrobot_sim/meshes/pipetting_robot/collision/link1.STL"/>
      </geometry>
    </collision>
  </link>
  <joint name="shoulder_joint" type="revolute">
    <origin rpy="0 0 3.1415926535897932384626433832795" xyz="0 0 0.122"/>
    <parent link="base_link"/>
    <child link="shoulder_Link"/>
    <axis xyz="0 0 1"/>
    <limit effort="500" lower="-6.283185307179586476925286766559" start_stop="207" upper="6.283185307179586476925286766559" velocity="2.5964"/>
    <property collision_detection_para="50 50 30 20" damping="0" equa_inertia="1.5" inertia="2.027236783" motor_constant="8.72" offset="0" protect_max_torque="80.0" ratio="121" stiffness="0"/>
  </joint>
  <transmission name="trans_shoulder_joint">
    <type>transmission_interface/SimpleTransmission</type>
    <joint name="shoulder_joint">
      <hardwareInterface>hardware_interface/PositionJointInterface</hardwareInterface>
    </joint>
    <actuator name="motor_shoulder_joint">
      <hardwareInterface>hardware_interface/PositionJointInterface</hardwareInterface>
    </actuator>
    <mechanicalReduction>1</mechanicalReduction>
  </transmission>
  <link name="upperArm_Link">
    <inertial>
      <origin rpy="0 0 0" xyz="0.2040 0 0.006603"/>
      <mass value="10.836261"/>
      <inertia ixx="0.026024" ixy="0.00002" ixz="0" iyy="0.432805" iyz="0" izz="0.425155"/>
    </inertial>
    <visual>
      <origin rpy="0 0 0" xyz="0 0 0"/>
      <geometry>
        <mesh filename="/home/robot/pipetbot_ros2_ws/install/pipettingrobot_sim/share/pipettingrobot_sim/meshes/pipetting_robot/visual/link2.DAE"/>
      </geometry>
      <material name="">
        <color rgba="1 1 1 1"/>
      </material>
    </visual>
    <collision name="upperArm_collision">
      <origin rpy="0 0 0" xyz="0 0 0"/>
      <geometry>
        <mesh filename="/home/robot/pipetbot_ros2_ws/install/pipettingrobot_sim/share/pipettingrobot_sim/meshes/pipetting_robot/collision/link2.STL"/>
      </geometry>
    </collision>
  </link>
  <joint name="upperArm_joint" type="revolute">
    <origin rpy="-1.5707963267948966192313216916398 -1.5707963267948966192313216916398 0" xyz="0 0.1215 0"/>
    <parent link="shoulder_Link"/>
    <child link="upperArm_Link"/>
    <axis xyz="0 0 1"/>
    <limit effort="133" lower="-6.283185307179586476925286766559" start_stop="207" upper="6.283185307179586476925286766559" velocity="2.5964"/>
    <property collision_detection_para="50 50 30 20" damping="0" equa_inertia="1.5" inertia="2.027236783" motor_constant="8.72" offset="0" protect_max_torque="80.0" ratio="121" stiffness="0"/>
  </joint>
  <transmission name="trans_upperArm_joint">
    <type>transmission_interface/SimpleTransmission</type>
    <joint name="upperArm_joint">
      <hardwareInterface>hardware_interface/PositionJointInterface</hardwareInterface>
    </joint>
    <actuator name="motor_upperArm_joint">
      <hardwareInterface>hardware_interface/PositionJointInterface</hardwareInterface>
    </actuator>
    <mechanicalReduction>1</mechanicalReduction>
  </transmission>
  <link name="foreArm_Link">
    <inertial>
      <origin rpy="0 0 0" xyz="0.264626 -0.00002 0.093611"/>
      <mass value="2.849168"/>
      <inertia ixx="0.003634" ixy="0.000007" ixz="0.000168" iyy="0.065327" iyz="0.000002" izz="0.064676"/>
    </inertial>
    <visual>
      <origin rpy="0 0 0" xyz="0 0 0"/>
      <geometry>
        <mesh filename="/home/robot/pipetbot_ros2_ws/install/pipettingrobot_sim/share/pipettingrobot_sim/meshes/pipetting_robot/visual/link3.DAE"/>
      </geometry>
      <material name="">
        <color rgba="1 1 1 1"/>
      </material>
    </visual>
    <collision name="foreArm_collision">
      <origin rpy="0 0 0" xyz="0 0 0"/>
      <geometry>
        <mesh filename="/home/robot/pipetbot_ros2_ws/install/pipettingrobot_sim/share/pipettingrobot_sim/meshes/pipetting_robot/collision/link3.STL"/>
      </geometry>
    </collision>
  </link>
  <joint name="foreArm_joint" type="revolute">
    <origin rpy="-3.1415926535897932384626433832795 0 0" xyz="0.408 0 0"/>
    <parent link="upperArm_Link"/>
    <child link="foreArm_Link"/>
    <axis xyz="0 0 1"/>
    <limit effort="133" lower="-6.283185307179586476925286766559" start_stop="207" upper="6.283185307179586476925286766559" velocity="2.5964"/>
    <property collision_detection_para="50 50 30 20" damping="0" equa_inertia="1.2" inertia="2.027236783" motor_constant="8.72" offset="0" protect_max_torque="60.0" ratio="121" stiffness="0"/>
  </joint>
  <transmission name="trans_foreArm_joint">
    <type>transmission_interface/SimpleTransmission</type>
    <joint name="foreArm_joint">
      <hardwareInterface>hardware_interface/PositionJointInterface</hardwareInterface>
    </joint>
    <actuator name="motor_foreArm_joint">
      <hardwareInterface>hardware_interface/PositionJointInterface</hardwareInterface>
    </actuator>
    <mechanicalReduction>1</mechanicalReduction>
  </transmission>
  <link name="wrist1_Link">
    <inertial>
      <origin rpy="0 0 0" xyz="0.000038 0.011278 -0.001539"/>
      <mass value="1.628022"/>
      <inertia ixx="0.001951" ixy="0.000003" ixz="0.000001" iyy="0.001154" iyz="-0.000042" izz="0.001931"/>
    </inertial>
    <visual>
      <origin rpy="0 0 0" xyz="0 0 0"/>
      <geometry>
        <mesh filename="/home/robot/pipetbot_ros2_ws/install/pipettingrobot_sim/share/pipettingrobot_sim/meshes/pipetting_robot/visual/link4.DAE"/>
      </geometry>
      <material name="">
        <color rgba="1 1 1 1"/>
      </material>
    </visual>
    <collision name="wrist1_collision">
      <origin rpy="0 0 0" xyz="0 0 0"/>
      <geometry>
        <mesh filename="/home/robot/pipetbot_ros2_ws/install/pipettingrobot_sim/share/pipettingrobot_sim/meshes/pipetting_robot/collision/link4.STL"/>
      </geometry>
    </collision>
  </link>
  <joint name="wrist1_joint" type="revolute">
    <origin rpy="3.1415926535897932384626433832795 0 1.5707963267948966192313216916398" xyz="0.376 0 0"/>
    <parent link="foreArm_Link"/>
    <child link="wrist1_Link"/>
    <axis xyz="0 0 1"/>
    <limit effort="13.5" lower="-6.283185307179586476925286766559" start_stop="34" upper="6.283185307179586476925286766559" velocity="3.1105"/>
    <property collision_detection_para="50 50 30 20" damping="0" equa_inertia="0.05" inertia="0.219280696" motor_constant="7.092" offset="0" protect_max_torque="16.0" ratio="101" stiffness="0"/>
  </joint>
  <transmission name="trans_wrist1_joint">
    <type>transmission_interface/SimpleTransmission</type>
    <joint name="wrist1_joint">
      <hardwareInterface>hardware_interface/PositionJointInterface</hardwareInterface>
    </joint>
    <actuator name="motor_wrist1_joint">
      <hardwareInterface>hardware_interface/PositionJointInterface</hardwareInterface>
    </actuator>
    <mechanicalReduction>1</mechanicalReduction>
  </transmission>
  <link name="wrist2_Link">
    <inertial>
      <origin rpy="0 0 0" xyz="-0.000038 -0.011278 -0.001539"/>
      <mass value="1.628022"/>
      <inertia ixx="0.001951" ixy="0.000003" ixz="-0.000001" iyy="0.001154" iyz="0.000042" izz="0.001931"/>
    </inertial>
    <visual>
      <origin rpy="0 0 0" xyz="0 0 0"/>
      <geometry>
        <mesh filename="/home/robot/pipetbot_ros2_ws/install/pipettingrobot_sim/share/pipettingrobot_sim/meshes/pipetting_robot/visual/link5.DAE"/>
      </geometry>
      <material name="">
        <color rgba="1 1 1 1"/>
      </material>
    </visual>
    <collision name="wrist2_collision">
      <origin rpy="0 0 0" xyz="0 0 0"/>
      <geometry>
        <mesh filename="/home/robot/pipetbot_ros2_ws/install/pipettingrobot_sim/share/pipettingrobot_sim/meshes/pipetting_robot/collision/link5.STL"/>
      </geometry>
    </collision>
  </link>
  <joint name="wrist2_joint" type="revolute">
    <origin rpy="-1.5707963267948966192313216916398 0 0" xyz="0 0.1025 0"/>
    <parent link="wrist1_Link"/>
    <child link="wrist2_Link"/>
    <axis xyz="0 0 1"/>
    <limit effort="13.5" lower="-6.283185307179586476925286766559" start_stop="34" upper="6.283185307179586476925286766559" velocity="3.1105"/>
    <property collision_detection_para="50 50 30 20" damping="0" equa_inertia="0.05" inertia="0.219280696" motor_constant="7.092" offset="0" protect_max_torque="16.0" ratio="101" stiffness="0"/>
  </joint>
  <transmission name="trans_wrist2_joint">
    <type>transmission_interface/SimpleTransmission</type>
    <joint name="wrist2_joint">
      <hardwareInterface>hardware_interface/PositionJointInterface</hardwareInterface>
    </joint>
    <actuator name="motor_wrist2_joint">
      <hardwareInterface>hardware_interface/PositionJointInterface</hardwareInterface>
    </actuator>
    <mechanicalReduction>1</mechanicalReduction>
  </transmission>
  <link name="wrist3_Link">
    <inertial>
      <origin rpy="0 0 0" xyz="0.000022 0.0006 -0.017081"/>
      <mass value="0.1978"/>
      <inertia ixx="0.000118" ixy="0" ixz="0" iyy="0.000112" iyz="0.000001" izz="0.000184"/>
    </inertial>
    <visual>
      <origin rpy="0 0 0" xyz="0 0 0"/>
      <geometry>
        <mesh filename="/home/robot/pipetbot_ros2_ws/install/pipettingrobot_sim/share/pipettingrobot_sim/meshes/pipetting_robot/visual/link6.DAE"/>
      </geometry>
      <material name="">
        <color rgba="1 1 1 1"/>
      </material>
    </visual>
    <collision name="wrist3_collision">
      <origin rpy="0 0 0" xyz="0 0 0"/>
      <geometry>
        <mesh filename="/home/robot/pipetbot_ros2_ws/install/pipettingrobot_sim/share/pipettingrobot_sim/meshes/pipetting_robot/collision/link6.STL"/>
      </geometry>
    </collision>
  </link>
  <joint name="wrist3_joint" type="revolute">
    <origin rpy="1.5707963267948966192313216916398 0 0" xyz="0 -0.094 0"/>
    <parent link="wrist2_Link"/>
    <child link="wrist3_Link"/>
    <axis xyz="0 0 1"/>
    <limit effort="13.5" lower="-6.283185307179586476925286766559" start_stop="34" upper="6.283185307179586476925286766559" velocity="3.1105"/>
    <property collision_detection_para="50 50 30 20" damping="0" equa_inertia="0.01" inertia="0.219280696" motor_constant="7.092" offset="0" protect_max_torque="10.0" ratio="101" stiffness="0"/>
  </joint>
  <transmission name="trans_wrist3_joint">
    <type>transmission_interface/SimpleTransmission</type>
    <joint name="wrist3_joint">
      <hardwareInterface>hardware_interface/PositionJointInterface</hardwareInterface>
    </joint>
    <actuator name="motor_wrist3_joint">
      <hardwareInterface>hardware_interface/PositionJointInterface</hardwareInterface>
    </actuator>
    <mechanicalReduction>1</mechanicalReduction>
  </transmission>
  <!-- pipettor  -->
  <link name="flange"/>
  <joint name="wrist3-flange" type="fixed">
    <parent link="wrist3_Link"/>
    <child link="flange"/>
    <origin rpy="0 0 0" xyz="0 0 0.002"/>
  </joint>
  <!-- ROS-Industrial 'tool0' frame - all-zeros tool frame -->
  <link name="tool0">
    <inertial>
      <origin rpy="-1.5707963267948966 3.141592653589793 0" xyz="0 -0.2374 0.104"/>
      <mass value="0.5"/>
      <inertia ixx="0.1" ixy="0.1" ixz="0.1" iyy="0.1" iyz="0.1" izz="0.1"/>
    </inertial>
    <visual>
      <origin rpy="-1.5707963267948966 3.141592653589793 0" xyz="0 -0.2374 0.104"/>
      <geometry>
        <mesh filename="/home/robot/pipetbot_ros2_ws/install/pipettingrobot_sim/share/pipettingrobot_sim/meshes/thirdparts/pipettor_link.STL"/>
      </geometry>
      <material name="">
        <color rgba="1 1 1 1"/>
      </material>
    </visual>
    <collision name="tool0_collision">
      <origin rpy="-1.5707963267948966 3.141592653589793 0" xyz="0 -0.2374 0.104"/>
      <geometry>
        <mesh filename="/home/robot/pipetbot_ros2_ws/install/pipettingrobot_sim/share/pipettingrobot_sim/meshes/thirdparts/pipettor_link.STL"/>
      </geometry>
    </collision>
  </link>
  <joint name="flange-tool0" type="fixed">
    <!-- default toolframe - X+ left, Y+ up, Z+ front -->
    <origin rpy="0 0 0" xyz="0 0 0"/>
    <parent link="flange"/>
    <child link="tool0"/>
  </joint>
  <link name="world"/>
  <joint name="world_to_support" type="fixed">
    <parent link="world"/>
    <child link="support_link"/>
    <!-- 支架底端与 world 原点对齐 -->
    <origin rpy="0 0 0" xyz="0.0 -0.3 0.0"/>
  </joint>
  <!-- base_link -->
  <gazebo reference="base_link">
    <sensor name="base_contact_sensor" type="contact">
      <always_on>true</always_on>
      <update_rate>100</update_rate>
      <contact>
        <collision>base_link::base_collision</collision>
      </contact>
      <plugin filename="libgazebo_ros_bumper.so" name="base_bumper_plugin">
        <ros>
          <namespace>/pipetting_robot</namespace>
          <remapping>bumper_states:=base_contact</remapping>
        </ros>
        <frame_name>base_link</frame_name>
      </plugin>
    </sensor>
  </gazebo>
  <!-- shoulder_Link -->
  <gazebo reference="shoulder_Link">
    <sensor name="shoulder_contact_sensor" type="contact">
      <always_on>true</always_on>
      <update_rate>100</update_rate>
      <contact>
        <collision>shoulder_Link::shoulder_collision</collision>
      </contact>
      <plugin filename="libgazebo_ros_bumper.so" name="shoulder_bumper_plugin">
        <ros>
          <namespace>/pipetting_robot</namespace>
          <remapping>bumper_states:=shoulder_contact</remapping>
        </ros>
        <frame_name>shoulder_Link</frame_name>
      </plugin>
    </sensor>
  </gazebo>
  <!-- upperArm_Link -->
  <gazebo reference="upperArm_Link">
    <sensor name="upperArm_contact_sensor" type="contact">
      <always_on>true</always_on>
      <update_rate>100</update_rate>
      <contact>
        <collision>pipetting_robot::upperArm_Link::upperArm_collision</collision>
      </contact>
      <plugin filename="libgazebo_ros_bumper.so" name="upperArm_bumper_plugin">
        <ros>
          <namespace>/pipetting_robot</namespace>
          <remapping>bumper_states:=upperArm_contact</remapping>
        </ros>
        <frame_name>upperArm_Link</frame_name>
      </plugin>
    </sensor>
  </gazebo>
  <!-- foreArm_Link -->
  <gazebo reference="foreArm_Link">
    <sensor name="foreArm_contact_sensor" type="contact">
      <always_on>true</always_on>
      <update_rate>100</update_rate>
      <contact>
        <collision>pipetting_robot::foreArm_Link::foreArm_collision</collision>
      </contact>
      <plugin filename="libgazebo_ros_bumper.so" name="foreArm_bumper_plugin">
        <ros>
          <namespace>/pipetting_robot</namespace>
          <remapping>bumper_states:=foreArm_contact</remapping>
        </ros>
        <frame_name>foreArm_Link</frame_name>
      </plugin>
    </sensor>
  </gazebo>
  <!-- wrist1_Link -->
  <gazebo reference="wrist1_Link">
    <sensor name="wrist1_contact_sensor" type="contact">
      <always_on>true</always_on>
      <update_rate>100</update_rate>
      <contact>
        <collision>pipetting_robot::wrist1_Link::wrist1_collision</collision>
      </contact>
      <plugin filename="libgazebo_ros_bumper.so" name="wrist1_bumper_plugin">
        <ros>
          <namespace>/pipetting_robot</namespace>
          <remapping>bumper_states:=wrist1_contact</remapping>
        </ros>
        <frame_name>wrist1_Link</frame_name>
      </plugin>
    </sensor>
  </gazebo>
  <!-- wrist2_Link -->
  <gazebo reference="wrist2_Link">
    <sensor name="wrist2_contact_sensor" type="contact">
      <always_on>true</always_on>
      <update_rate>100</update_rate>
      <contact>
        <collision>pipetting_robot::wrist2_Link::wrist2_collision</collision>
      </contact>
      <plugin filename="libgazebo_ros_bumper.so" name="wrist2_bumper_plugin">
        <ros>
          <namespace>/pipetting_robot</namespace>
          <remapping>bumper_states:=wrist2_contact</remapping>
        </ros>
        <frame_name>wrist2_Link</frame_name>
      </plugin>
    </sensor>
  </gazebo>
  <!-- wrist3_Link -->
  <gazebo reference="wrist3_Link">
    <sensor name="wrist3_contact_sensor" type="contact">
      <always_on>true</always_on>
      <update_rate>100</update_rate>
      <contact>
        <collision>pipetting_robot::wrist3_Link::wrist3_collision</collision>
      </contact>
      <plugin filename="libgazebo_ros_bumper.so" name="wrist3_bumper_plugin">
        <ros>
          <namespace>/pipetting_robot</namespace>
          <remapping>bumper_states:=wrist3_contact</remapping>
        </ros>
        <frame_name>wrist3_Link</frame_name>
      </plugin>
    </sensor>
  </gazebo>
  <!-- tool0 -->
  <gazebo reference="tool0">
    <sensor name="tool0_contact_sensor" type="contact">
      <always_on>true</always_on>
      <update_rate>100</update_rate>
      <contact>
        <collision>pipetting_robot::tool0::tool0_collision</collision>
      </contact>
      <plugin filename="libgazebo_ros_bumper.so" name="tool0_bumper_plugin">
        <ros>
          <namespace>/pipetting_robot</namespace>
          <remapping>bumper_states:=tool0_contact</remapping>
        </ros>
        <frame_name>tool0</frame_name>
      </plugin>
    </sensor>
  </gazebo>
</robot>
