<sdf version='1.7'>
  <world name='default'>
    <physics type='ode'>
      <max_step_size>0.001</max_step_size>
      <real_time_factor>1</real_time_factor>
      <real_time_update_rate>1000</real_time_update_rate>
      <gravity>0 0 -9.8</gravity>
    </physics>
    <light name='sun' type='directional'>
      <cast_shadows>1</cast_shadows>
      <pose>0 0 10 0 -0 0</pose>
      <diffuse>0.8 0.8 0.8 1</diffuse>
      <specular>0.2 0.2 0.2 1</specular>
      <attenuation>
        <range>1000</range>
        <constant>0.9</constant>
        <linear>0.01</linear>
        <quadratic>0.001</quadratic>
      </attenuation>
      <direction>-0.5 0.1 -0.9</direction>
      <spot>
        <inner_angle>0</inner_angle>
        <outer_angle>0</outer_angle>
        <falloff>0</falloff>
      </spot>
    </light>
    <model name='ground_plane'>
      <static>1</static>
      <link name='link'>
        <collision name='collision'>
          <geometry>
            <plane>
              <normal>0 0 1</normal>
              <size>100 100</size>
            </plane>
          </geometry>
          <surface>
            <friction>
              <ode>
                <mu>100</mu>
                <mu2>50</mu2>
              </ode>
              <torsional>
                <ode/>
              </torsional>
            </friction>
            <contact>
              <ode/>
            </contact>
            <bounce/>
          </surface>
          <max_contacts>10</max_contacts>
        </collision>
        <visual name='visual'>
          <cast_shadows>0</cast_shadows>
          <geometry>
            <plane>
              <normal>0 0 1</normal>
              <size>100 100</size>
            </plane>
          </geometry>
          <material>
            <script>
              <uri>file://media/materials/scripts/gazebo.material</uri>
              <name>Gazebo/Grey</name>
            </script>
          </material>
        </visual>
        <self_collide>0</self_collide>
        <enable_wind>0</enable_wind>
        <kinematic>0</kinematic>
      </link>
    </model>
    <scene>
      <ambient>0.4 0.4 0.4 1</ambient>
      <background>0.7 0.7 0.7 1</background>
      <shadows>0</shadows>
    </scene>
    <gravity>0 0 -9.8</gravity>
    <magnetic_field>6e-06 2.3e-05 -4.2e-05</magnetic_field>
    <atmosphere type='adiabatic'/>
    <audio>
      <device>default</device>
    </audio>
    <wind/>
    <spherical_coordinates>
      <surface_model>EARTH_WGS84</surface_model>
      <latitude_deg>0</latitude_deg>
      <longitude_deg>0</longitude_deg>
      <elevation>0</elevation>
      <heading_deg>0</heading_deg>
    </spherical_coordinates>
    <model name='pipetting_robot'>
      <joint name='world_joint' type='fixed'>
        <pose relative_to='__model__'>0 0 0.85 0 -0 0</pose>
        <parent>world</parent>
        <child>base_link</child>
      </joint>
      <link name='base_link'>
        <pose relative_to='world_joint'>0 0 0 0 -0 0</pose>
        <inertial>
          <pose>0.000129 0.001249 0.016678 0 -0 0</pose>
          <mass>1.53902</mass>
          <inertia>
            <ixx>0.003278</ixx>
            <ixy>-1e-06</ixy>
            <ixz>-1e-06</ixz>
            <iyy>0.003017</iyy>
            <iyz>-4.8e-05</iyz>
            <izz>0.005841</izz>
          </inertia>
        </inertial>
        <collision name='base_link_collision'>
          <pose>0 0 0 0 -0 0</pose>
          <geometry>
            <mesh>
              <scale>1 1 1</scale>
              <uri>/home/robot/aubo_ros2_ws/install/pipettingrobot_sim/share/pipettingrobot_sim/meshes/pipetting_robot/collision/link0.STL</uri>
            </mesh>
          </geometry>
          <max_contacts>10</max_contacts>
          <surface>
            <contact>
              <ode/>
            </contact>
            <bounce/>
            <friction>
              <torsional>
                <ode/>
              </torsional>
              <ode/>
            </friction>
          </surface>
        </collision>
        <visual name='base_link_visual'>
          <pose>0 0 0 0 -0 0</pose>
          <geometry>
            <mesh>
              <scale>1 1 1</scale>
              <uri>/home/robot/aubo_ros2_ws/install/pipettingrobot_sim/share/pipettingrobot_sim/meshes/pipetting_robot/visual/link0.DAE</uri>
            </mesh>
          </geometry>
        </visual>
        <self_collide>0</self_collide>
        <enable_wind>0</enable_wind>
        <kinematic>0</kinematic>
      </link>
      <joint name='shoulder_joint' type='revolute'>
        <pose relative_to='base_link'>0 0 0.122 0 -0 3.14159</pose>
        <parent>base_link</parent>
        <child>shoulder_Link</child>
        <axis>
          <xyz>0 0 1</xyz>
          <limit>
            <lower>-6.28319</lower>
            <upper>6.28319</upper>
            <effort>500</effort>
            <velocity>2.5964</velocity>
          </limit>
          <dynamics>
            <spring_reference>0</spring_reference>
            <spring_stiffness>0</spring_stiffness>
          </dynamics>
        </axis>
      </joint>
      <link name='shoulder_Link'>
        <pose relative_to='shoulder_joint'>0 0 0 0 -0 0</pose>
        <inertial>
          <pose>-1e-05 0.001807 -0.013854 0 -0 0</pose>
          <mass>4.84858</mass>
          <inertia>
            <ixx>0.011842</ixx>
            <ixy>0</ixy>
            <ixz>4e-06</ixz>
            <iyy>0.0118</iyy>
            <iyz>-0.000103</iyz>
            <izz>0.008103</izz>
          </inertia>
        </inertial>
        <collision name='shoulder_Link_collision'>
          <pose>0 0 0 0 -0 0</pose>
          <geometry>
            <mesh>
              <scale>1 1 1</scale>
              <uri>/home/robot/aubo_ros2_ws/install/pipettingrobot_sim/share/pipettingrobot_sim/meshes/pipetting_robot/collision/link1.STL</uri>
            </mesh>
          </geometry>
          <max_contacts>10</max_contacts>
          <surface>
            <contact>
              <ode/>
            </contact>
            <bounce/>
            <friction>
              <torsional>
                <ode/>
              </torsional>
              <ode/>
            </friction>
          </surface>
        </collision>
        <visual name='shoulder_Link_visual'>
          <pose>0 0 0 0 -0 0</pose>
          <geometry>
            <mesh>
              <scale>1 1 1</scale>
              <uri>/home/robot/aubo_ros2_ws/install/pipettingrobot_sim/share/pipettingrobot_sim/meshes/pipetting_robot/visual/link1.DAE</uri>
            </mesh>
          </geometry>
        </visual>
        <self_collide>0</self_collide>
        <enable_wind>0</enable_wind>
        <kinematic>0</kinematic>
      </link>
      <joint name='upperArm_joint' type='revolute'>
        <pose relative_to='shoulder_Link'>0 0.1215 0 1.57079 -1.57079 3.14159</pose>
        <parent>shoulder_Link</parent>
        <child>upperArm_Link</child>
        <axis>
          <xyz>0 0 1</xyz>
          <limit>
            <lower>-6.28319</lower>
            <upper>6.28319</upper>
            <effort>133</effort>
            <velocity>2.5964</velocity>
          </limit>
          <dynamics>
            <spring_reference>0</spring_reference>
            <spring_stiffness>0</spring_stiffness>
          </dynamics>
        </axis>
      </joint>
      <link name='upperArm_Link'>
        <pose relative_to='upperArm_joint'>0 0 0 0 -0 0</pose>
        <inertial>
          <pose>0.204 0 0.006603 0 -0 0</pose>
          <mass>10.8363</mass>
          <inertia>
            <ixx>0.026024</ixx>
            <ixy>2e-05</ixy>
            <ixz>0</ixz>
            <iyy>0.432805</iyy>
            <iyz>0</iyz>
            <izz>0.425155</izz>
          </inertia>
        </inertial>
        <collision name='upperArm_Link_collision'>
          <pose>0 0 0 0 -0 0</pose>
          <geometry>
            <mesh>
              <scale>1 1 1</scale>
              <uri>/home/robot/aubo_ros2_ws/install/pipettingrobot_sim/share/pipettingrobot_sim/meshes/pipetting_robot/collision/link2.STL</uri>
            </mesh>
          </geometry>
          <max_contacts>10</max_contacts>
          <surface>
            <contact>
              <ode/>
            </contact>
            <bounce/>
            <friction>
              <torsional>
                <ode/>
              </torsional>
              <ode/>
            </friction>
          </surface>
        </collision>
        <visual name='upperArm_Link_visual'>
          <pose>0 0 0 0 -0 0</pose>
          <geometry>
            <mesh>
              <scale>1 1 1</scale>
              <uri>/home/robot/aubo_ros2_ws/install/pipettingrobot_sim/share/pipettingrobot_sim/meshes/pipetting_robot/visual/link2.DAE</uri>
            </mesh>
          </geometry>
        </visual>
        <self_collide>0</self_collide>
        <enable_wind>0</enable_wind>
        <kinematic>0</kinematic>
      </link>
      <joint name='foreArm_joint' type='revolute'>
        <pose relative_to='upperArm_Link'>0.408 0 0 -3.14159 0 0</pose>
        <parent>upperArm_Link</parent>
        <child>foreArm_Link</child>
        <axis>
          <xyz>0 0 1</xyz>
          <limit>
            <lower>-6.28319</lower>
            <upper>6.28319</upper>
            <effort>133</effort>
            <velocity>2.5964</velocity>
          </limit>
          <dynamics>
            <spring_reference>0</spring_reference>
            <spring_stiffness>0</spring_stiffness>
          </dynamics>
        </axis>
      </joint>
      <link name='foreArm_Link'>
        <pose relative_to='foreArm_joint'>0 0 0 0 -0 0</pose>
        <inertial>
          <pose>0.264626 -2e-05 0.093611 0 -0 0</pose>
          <mass>2.84917</mass>
          <inertia>
            <ixx>0.003634</ixx>
            <ixy>7e-06</ixy>
            <ixz>0.000168</ixz>
            <iyy>0.065327</iyy>
            <iyz>2e-06</iyz>
            <izz>0.064676</izz>
          </inertia>
        </inertial>
        <collision name='foreArm_Link_collision'>
          <pose>0 0 0 0 -0 0</pose>
          <geometry>
            <mesh>
              <scale>1 1 1</scale>
              <uri>/home/robot/aubo_ros2_ws/install/pipettingrobot_sim/share/pipettingrobot_sim/meshes/pipetting_robot/collision/link3.STL</uri>
            </mesh>
          </geometry>
          <max_contacts>10</max_contacts>
          <surface>
            <contact>
              <ode/>
            </contact>
            <bounce/>
            <friction>
              <torsional>
                <ode/>
              </torsional>
              <ode/>
            </friction>
          </surface>
        </collision>
        <visual name='foreArm_Link_visual'>
          <pose>0 0 0 0 -0 0</pose>
          <geometry>
            <mesh>
              <scale>1 1 1</scale>
              <uri>/home/robot/aubo_ros2_ws/install/pipettingrobot_sim/share/pipettingrobot_sim/meshes/pipetting_robot/visual/link3.DAE</uri>
            </mesh>
          </geometry>
        </visual>
        <self_collide>0</self_collide>
        <enable_wind>0</enable_wind>
        <kinematic>0</kinematic>
      </link>
      <joint name='wrist1_joint' type='revolute'>
        <pose relative_to='foreArm_Link'>0.376 0 0 3.14159 -0 1.5708</pose>
        <parent>foreArm_Link</parent>
        <child>wrist1_Link</child>
        <axis>
          <xyz>0 0 1</xyz>
          <limit>
            <lower>-6.28319</lower>
            <upper>6.28319</upper>
            <effort>13.5</effort>
            <velocity>3.1105</velocity>
          </limit>
          <dynamics>
            <spring_reference>0</spring_reference>
            <spring_stiffness>0</spring_stiffness>
          </dynamics>
        </axis>
      </joint>
      <link name='wrist1_Link'>
        <pose relative_to='wrist1_joint'>0 0 0 0 -0 0</pose>
        <inertial>
          <pose>3.8e-05 0.011278 -0.001539 0 -0 0</pose>
          <mass>1.62802</mass>
          <inertia>
            <ixx>0.001951</ixx>
            <ixy>3e-06</ixy>
            <ixz>1e-06</ixz>
            <iyy>0.001154</iyy>
            <iyz>-4.2e-05</iyz>
            <izz>0.001931</izz>
          </inertia>
        </inertial>
        <collision name='wrist1_Link_collision'>
          <pose>0 0 0 0 -0 0</pose>
          <geometry>
            <mesh>
              <scale>1 1 1</scale>
              <uri>/home/robot/aubo_ros2_ws/install/pipettingrobot_sim/share/pipettingrobot_sim/meshes/pipetting_robot/collision/link4.STL</uri>
            </mesh>
          </geometry>
          <max_contacts>10</max_contacts>
          <surface>
            <contact>
              <ode/>
            </contact>
            <bounce/>
            <friction>
              <torsional>
                <ode/>
              </torsional>
              <ode/>
            </friction>
          </surface>
        </collision>
        <visual name='wrist1_Link_visual'>
          <pose>0 0 0 0 -0 0</pose>
          <geometry>
            <mesh>
              <scale>1 1 1</scale>
              <uri>/home/robot/aubo_ros2_ws/install/pipettingrobot_sim/share/pipettingrobot_sim/meshes/pipetting_robot/visual/link4.DAE</uri>
            </mesh>
          </geometry>
        </visual>
        <self_collide>0</self_collide>
        <enable_wind>0</enable_wind>
        <kinematic>0</kinematic>
      </link>
      <joint name='wrist2_joint' type='revolute'>
        <pose relative_to='wrist1_Link'>0 0.1025 0 -1.5708 0 0</pose>
        <parent>wrist1_Link</parent>
        <child>wrist2_Link</child>
        <axis>
          <xyz>0 0 1</xyz>
          <limit>
            <lower>-6.28319</lower>
            <upper>6.28319</upper>
            <effort>13.5</effort>
            <velocity>3.1105</velocity>
          </limit>
          <dynamics>
            <spring_reference>0</spring_reference>
            <spring_stiffness>0</spring_stiffness>
          </dynamics>
        </axis>
      </joint>
      <link name='wrist2_Link'>
        <pose relative_to='wrist2_joint'>0 0 0 0 -0 0</pose>
        <inertial>
          <pose>-3.8e-05 -0.011278 -0.001539 0 -0 0</pose>
          <mass>1.62802</mass>
          <inertia>
            <ixx>0.001951</ixx>
            <ixy>3e-06</ixy>
            <ixz>-1e-06</ixz>
            <iyy>0.001154</iyy>
            <iyz>4.2e-05</iyz>
            <izz>0.001931</izz>
          </inertia>
        </inertial>
        <collision name='wrist2_Link_collision'>
          <pose>0 0 0 0 -0 0</pose>
          <geometry>
            <mesh>
              <scale>1 1 1</scale>
              <uri>/home/robot/aubo_ros2_ws/install/pipettingrobot_sim/share/pipettingrobot_sim/meshes/pipetting_robot/collision/link5.STL</uri>
            </mesh>
          </geometry>
          <max_contacts>10</max_contacts>
          <surface>
            <contact>
              <ode/>
            </contact>
            <bounce/>
            <friction>
              <torsional>
                <ode/>
              </torsional>
              <ode/>
            </friction>
          </surface>
        </collision>
        <visual name='wrist2_Link_visual'>
          <pose>0 0 0 0 -0 0</pose>
          <geometry>
            <mesh>
              <scale>1 1 1</scale>
              <uri>/home/robot/aubo_ros2_ws/install/pipettingrobot_sim/share/pipettingrobot_sim/meshes/pipetting_robot/visual/link5.DAE</uri>
            </mesh>
          </geometry>
        </visual>
        <self_collide>0</self_collide>
        <enable_wind>0</enable_wind>
        <kinematic>0</kinematic>
      </link>
      <joint name='wrist3_joint' type='revolute'>
        <pose relative_to='wrist2_Link'>0 -0.094 0 1.5708 -0 0</pose>
        <parent>wrist2_Link</parent>
        <child>wrist3_Link</child>
        <axis>
          <xyz>0 0 1</xyz>
          <limit>
            <lower>-6.28319</lower>
            <upper>6.28319</upper>
            <effort>13.5</effort>
            <velocity>3.1105</velocity>
          </limit>
          <dynamics>
            <spring_reference>0</spring_reference>
            <spring_stiffness>0</spring_stiffness>
          </dynamics>
        </axis>
      </joint>
      <link name='wrist3_Link'>
        <pose relative_to='wrist3_joint'>0 0 0 0 -0 0</pose>
        <inertial>
          <pose>6e-06 -0.169936 0.071111 0 -0 0</pose>
          <mass>0.6978</mass>
          <inertia>
            <ixx>0.0102933</ixx>
            <ixy>-7.42104e-07</ixy>
            <ixz>3.83777e-07</ixz>
            <iyy>0.00225908</iyy>
            <iyz>0.00415277</iyz>
            <izz>0.00821222</izz>
          </inertia>
        </inertial>
        <collision name='wrist3_Link_collision'>
          <pose>0 0 0 0 -0 0</pose>
          <geometry>
            <mesh>
              <scale>1 1 1</scale>
              <uri>/home/robot/aubo_ros2_ws/install/pipettingrobot_sim/share/pipettingrobot_sim/meshes/pipetting_robot/collision/link6.STL</uri>
            </mesh>
          </geometry>
          <max_contacts>10</max_contacts>
          <surface>
            <contact>
              <ode/>
            </contact>
            <bounce/>
            <friction>
              <torsional>
                <ode/>
              </torsional>
              <ode/>
            </friction>
          </surface>
        </collision>
        <collision name='wrist3_Link_fixed_joint_lump__tool0_collision_1'>
          <pose>0 -0.2374 0.106 1.5708 -0 3.14159</pose>
          <geometry>
            <mesh>
              <scale>1 1 1</scale>
              <uri>/home/robot/aubo_ros2_ws/install/pipettingrobot_sim/share/pipettingrobot_sim/meshes/thirdparts/pipettor_link.STL</uri>
            </mesh>
          </geometry>
          <max_contacts>10</max_contacts>
          <surface>
            <contact>
              <ode/>
            </contact>
            <bounce/>
            <friction>
              <torsional>
                <ode/>
              </torsional>
              <ode/>
            </friction>
          </surface>
        </collision>
        <visual name='wrist3_Link_visual'>
          <pose>0 0 0 0 -0 0</pose>
          <geometry>
            <mesh>
              <scale>1 1 1</scale>
              <uri>/home/robot/aubo_ros2_ws/install/pipettingrobot_sim/share/pipettingrobot_sim/meshes/pipetting_robot/visual/link6.DAE</uri>
            </mesh>
          </geometry>
        </visual>
        <visual name='wrist3_Link_fixed_joint_lump__tool0_visual_1'>
          <pose>0 -0.2374 0.106 1.5708 -0 3.14159</pose>
          <geometry>
            <mesh>
              <scale>1 1 1</scale>
              <uri>/home/robot/aubo_ros2_ws/install/pipettingrobot_sim/share/pipettingrobot_sim/meshes/thirdparts/pipettor_link.STL</uri>
            </mesh>
          </geometry>
        </visual>
        <self_collide>0</self_collide>
        <enable_wind>0</enable_wind>
        <kinematic>0</kinematic>
      </link>
      <static>0</static>
      <plugin name='gazebo_ros2_control' filename='libgazebo_ros2_control.so'>
        <parameters>/home/robot/aubo_ros2_ws/install/pipettingrobot_sim/share/pipettingrobot_sim/config/ros2_controllers.yaml</parameters>
      </plugin>
      <pose>0 0 0.05 0 -0 0</pose>
    </model>
    <model name='table_marble'>
      <static>1</static>
      <pose>1.40825 -0.089493 0.648 0 -0 0</pose>
      <link name='link'>
        <collision name='collision'>
          <geometry>
            <mesh>
              <uri>model:///table_marble/meshes/table_lightmap.dae</uri>
              <scale>0.25 0.25 0.25</scale>
            </mesh>
          </geometry>
          <max_contacts>10</max_contacts>
          <surface>
            <contact>
              <ode/>
            </contact>
            <bounce/>
            <friction>
              <torsional>
                <ode/>
              </torsional>
              <ode/>
            </friction>
          </surface>
        </collision>
        <visual name='visual'>
          <geometry>
            <mesh>
              <uri>model://table_marble/meshes/table_lightmap.dae</uri>
              <scale>0.25 0.25 0.25</scale>
            </mesh>
          </geometry>
          <material>
            <script>
              <uri>model://table_marble/materials/scripts</uri>
              <uri>model://table_marble/materials/textures</uri>
              <name>Table/Marble_Lightmap</name>
            </script>
            <lighting>0</lighting>
          </material>
        </visual>
        <self_collide>0</self_collide>
        <enable_wind>0</enable_wind>
        <kinematic>0</kinematic>
      </link>
    </model>
    <model name='plastic_cup'>
      <link name='link'>
        <pose>0 0 0.065 0 -0 0</pose>
        <inertial>
          <mass>0.0599</mass>
          <inertia>
            <ixx>0.000302896</ixx>
            <ixy>0</ixy>
            <ixz>0</ixz>
            <iyy>0.000302896</iyy>
            <iyz>0</iyz>
            <izz>3.28764e-05</izz>
          </inertia>
          <pose>0 0 0 0 -0 0</pose>
        </inertial>
        <collision name='collision'>
          <geometry>
            <mesh>
              <uri>model://plastic_cup/meshes/plastic_cup.dae</uri>
            </mesh>
          </geometry>
          <surface>
            <contact>
              <poissons_ratio>0.35</poissons_ratio>
              <elastic_modulus>3.10264e+09</elastic_modulus>
              <ode>
                <kp>100000</kp>
                <kd>100</kd>
                <max_vel>100</max_vel>
                <min_depth>0.001</min_depth>
              </ode>
            </contact>
            <friction>
              <torsional>
                <coefficient>1</coefficient>
                <use_patch_radius>0</use_patch_radius>
                <surface_radius>0.01</surface_radius>
                <ode/>
              </torsional>
              <ode/>
            </friction>
            <bounce/>
          </surface>
          <max_contacts>10</max_contacts>
        </collision>
        <visual name='visual'>
          <geometry>
            <mesh>
              <uri>model://plastic_cup/meshes/plastic_cup.dae</uri>
            </mesh>
          </geometry>
          <material>
            <script>
              <uri>file://media/materials/scripts/gazebo.material</uri>
              <name>Gazebo/GreyTransparent</name>
            </script>
          </material>
        </visual>
        <self_collide>0</self_collide>
        <enable_wind>0</enable_wind>
        <kinematic>0</kinematic>
      </link>
      <pose>-0.011222 -0.603602 0 0 -0 0</pose>
    </model>
    <model name='plastic_cup_clone'>
      <link name='link'>
        <pose>0 0 0.065 0 -0 0</pose>
        <inertial>
          <mass>0.0599</mass>
          <inertia>
            <ixx>0.000302896</ixx>
            <ixy>0</ixy>
            <ixz>0</ixz>
            <iyy>0.000302896</iyy>
            <iyz>0</iyz>
            <izz>3.28764e-05</izz>
          </inertia>
          <pose>0 0 0 0 -0 0</pose>
        </inertial>
        <collision name='collision'>
          <geometry>
            <mesh>
              <uri>model://plastic_cup/meshes/plastic_cup.dae</uri>
            </mesh>
          </geometry>
          <surface>
            <contact>
              <poissons_ratio>0.35</poissons_ratio>
              <elastic_modulus>3.10264e+09</elastic_modulus>
              <ode>
                <kp>100000</kp>
                <kd>100</kd>
                <max_vel>100</max_vel>
                <min_depth>0.001</min_depth>
              </ode>
            </contact>
            <friction>
              <torsional>
                <coefficient>1</coefficient>
                <use_patch_radius>0</use_patch_radius>
                <surface_radius>0.01</surface_radius>
                <ode/>
              </torsional>
              <ode/>
            </friction>
            <bounce/>
          </surface>
          <max_contacts>10</max_contacts>
        </collision>
        <visual name='visual'>
          <geometry>
            <mesh>
              <uri>model://plastic_cup/meshes/plastic_cup.dae</uri>
            </mesh>
          </geometry>
          <material>
            <script>
              <uri>file://media/materials/scripts/gazebo.material</uri>
              <name>Gazebo/GreyTransparent</name>
            </script>
          </material>
        </visual>
        <self_collide>0</self_collide>
        <enable_wind>0</enable_wind>
        <kinematic>0</kinematic>
      </link>
      <pose>0.990365 -0.07995 0.971703 0.015167 -0.003021 1.51295</pose>
    </model>
    <model name='plastic_cup_clone_1'>
      <link name='link'>
        <pose>0 0 0.065 0 -0 0</pose>
        <inertial>
          <mass>0.0599</mass>
          <inertia>
            <ixx>0.000302896</ixx>
            <ixy>0</ixy>
            <ixz>0</ixz>
            <iyy>0.000302896</iyy>
            <iyz>0</iyz>
            <izz>3.28764e-05</izz>
          </inertia>
          <pose>0 0 0 0 -0 0</pose>
        </inertial>
        <collision name='collision'>
          <geometry>
            <mesh>
              <uri>model://plastic_cup/meshes/plastic_cup.dae</uri>
            </mesh>
          </geometry>
          <surface>
            <contact>
              <poissons_ratio>0.35</poissons_ratio>
              <elastic_modulus>3.10264e+09</elastic_modulus>
              <ode>
                <kp>100000</kp>
                <kd>100</kd>
                <max_vel>100</max_vel>
                <min_depth>0.001</min_depth>
              </ode>
            </contact>
            <friction>
              <torsional>
                <coefficient>1</coefficient>
                <use_patch_radius>0</use_patch_radius>
                <surface_radius>0.01</surface_radius>
                <ode/>
              </torsional>
              <ode/>
            </friction>
            <bounce/>
          </surface>
          <max_contacts>10</max_contacts>
        </collision>
        <visual name='visual'>
          <geometry>
            <mesh>
              <uri>model://plastic_cup/meshes/plastic_cup.dae</uri>
            </mesh>
          </geometry>
          <material>
            <script>
              <uri>file://media/materials/scripts/gazebo.material</uri>
              <name>Gazebo/GreyTransparent</name>
            </script>
          </material>
        </visual>
        <self_collide>0</self_collide>
        <enable_wind>0</enable_wind>
        <kinematic>0</kinematic>
      </link>
      <pose>1.06449 -0.315664 0.971627 0.011249 -0.00224 1.51296</pose>
    </model>
    <model name='plastic_cup_clone_2'>
      <link name='link'>
        <pose>0 0 0.065 0 -0 0</pose>
        <inertial>
          <mass>0.0599</mass>
          <inertia>
            <ixx>0.000302896</ixx>
            <ixy>0</ixy>
            <ixz>0</ixz>
            <iyy>0.000302896</iyy>
            <iyz>0</iyz>
            <izz>3.28764e-05</izz>
          </inertia>
          <pose>0 0 0 0 -0 0</pose>
        </inertial>
        <collision name='collision'>
          <geometry>
            <mesh>
              <uri>model://plastic_cup/meshes/plastic_cup.dae</uri>
            </mesh>
          </geometry>
          <surface>
            <contact>
              <poissons_ratio>0.35</poissons_ratio>
              <elastic_modulus>3.10264e+09</elastic_modulus>
              <ode>
                <kp>100000</kp>
                <kd>100</kd>
                <max_vel>100</max_vel>
                <min_depth>0.001</min_depth>
              </ode>
            </contact>
            <friction>
              <torsional>
                <coefficient>1</coefficient>
                <use_patch_radius>0</use_patch_radius>
                <surface_radius>0.01</surface_radius>
                <ode/>
              </torsional>
              <ode/>
            </friction>
            <bounce/>
          </surface>
          <max_contacts>10</max_contacts>
        </collision>
        <visual name='visual'>
          <geometry>
            <mesh>
              <uri>model://plastic_cup/meshes/plastic_cup.dae</uri>
            </mesh>
          </geometry>
          <material>
            <script>
              <uri>file://media/materials/scripts/gazebo.material</uri>
              <name>Gazebo/GreyTransparent</name>
            </script>
          </material>
        </visual>
        <self_collide>0</self_collide>
        <enable_wind>0</enable_wind>
        <kinematic>0</kinematic>
      </link>
      <pose>0.943456 0.49037 0.971587 0.009247 -0.001839 1.51297</pose>
    </model>
    <model name='plastic_cup_clone_3'>
      <link name='link'>
        <pose>0 0 0.065 0 -0 0</pose>
        <inertial>
          <mass>0.0599</mass>
          <inertia>
            <ixx>0.000302896</ixx>
            <ixy>0</ixy>
            <ixz>0</ixz>
            <iyy>0.000302896</iyy>
            <iyz>0</iyz>
            <izz>3.28764e-05</izz>
          </inertia>
          <pose>0 0 0 0 -0 0</pose>
        </inertial>
        <collision name='collision'>
          <geometry>
            <mesh>
              <uri>model://plastic_cup/meshes/plastic_cup.dae</uri>
            </mesh>
          </geometry>
          <surface>
            <contact>
              <poissons_ratio>0.35</poissons_ratio>
              <elastic_modulus>3.10264e+09</elastic_modulus>
              <ode>
                <kp>100000</kp>
                <kd>100</kd>
                <max_vel>100</max_vel>
                <min_depth>0.001</min_depth>
              </ode>
            </contact>
            <friction>
              <torsional>
                <coefficient>1</coefficient>
                <use_patch_radius>0</use_patch_radius>
                <surface_radius>0.01</surface_radius>
                <ode/>
              </torsional>
              <ode/>
            </friction>
            <bounce/>
          </surface>
          <max_contacts>10</max_contacts>
        </collision>
        <visual name='visual'>
          <geometry>
            <mesh>
              <uri>model://plastic_cup/meshes/plastic_cup.dae</uri>
            </mesh>
          </geometry>
          <material>
            <script>
              <uri>file://media/materials/scripts/gazebo.material</uri>
              <name>Gazebo/GreyTransparent</name>
            </script>
          </material>
        </visual>
        <self_collide>0</self_collide>
        <enable_wind>0</enable_wind>
        <kinematic>0</kinematic>
      </link>
      <pose>1.338 0.168299 0.971548 0.007236 -0.001439 1.51297</pose>
    </model>
    <state world_name='default'>
      <sim_time>461 374000000</sim_time>
      <real_time>461 710702221</real_time>
      <wall_time>1745308855 629279967</wall_time>
      <iterations>461374</iterations>
      <model name='ground_plane'>
        <pose>0 0 0 0 -0 0</pose>
        <scale>1 1 1</scale>
        <link name='link'>
          <pose>0 0 0 0 -0 0</pose>
          <velocity>0 0 0 0 -0 0</velocity>
          <acceleration>0 0 0 0 -0 0</acceleration>
          <wrench>0 0 0 0 -0 0</wrench>
        </link>
      </model>
      <model name='pipetting_robot'>
        <pose>-0 -6.6e-05 0.050001 -7.6e-05 0 0</pose>
        <scale>1 1 1</scale>
        <link name='base_link'>
          <pose>-0 -1e-06 0.900001 -7.6e-05 0 0</pose>
          <velocity>-0 -0 -0 0 -0 0</velocity>
          <acceleration>-0 0 0 0 -0 0</acceleration>
          <wrench>-0 0 0 0 -0 0</wrench>
        </link>
        <link name='foreArm_Link'>
          <pose>3e-06 -0.121589 1.42998 0.003864 -1.57056 -1.57467</pose>
          <velocity>0 -0 -0 -0 -4e-06 -2e-06</velocity>
          <acceleration>-0.000273 0 -0 -2e-06 -0.003545 -0.040676</acceleration>
          <wrench>-0.000779 0 -0 0 -0 0</wrench>
        </link>
        <link name='shoulder_Link'>
          <pose>0 8e-06 1.022 -0.000159 -0 3.14159</pose>
          <velocity>0 0 -0 0 0 -2e-06</velocity>
          <acceleration>-4e-06 -0 -0 -2e-06 4.1e-05 -0.002295</acceleration>
          <wrench>-2e-05 -0 -0 0 -0 0</wrench>
        </link>
        <link name='upperArm_Link'>
          <pose>-1e-06 -0.121492 1.02198 3.09798 -1.57056 -1.5272</pose>
          <velocity>-0 0 -0 -0 2e-06 -2e-06</velocity>
          <acceleration>8.1e-05 -0 -0 -2e-06 0.001879 -0.037486</acceleration>
          <wrench>0.000875 -0 -0 0 -0 0</wrench>
        </link>
        <link name='wrist1_Link'>
          <pose>3e-06 -0.121677 1.80598 1.57102 3.1e-05 -1.3e-05</pose>
          <velocity>-1e-06 -0 -0 -0 1.2e-05 -2e-06</velocity>
          <acceleration>-0.000754 -0 -0 2.8e-05 0.007245 -0.004532</acceleration>
          <wrench>-0.001228 -0 -1e-06 0 -0 0</wrench>
        </link>
        <link name='wrist2_Link'>
          <pose>6e-06 -0.121701 1.90848 0.000245 3.1e-05 1.2e-05</pose>
          <velocity>0 -0 -0 0 1.2e-05 9e-06</velocity>
          <acceleration>0.000411 -0 0 0 0.011872 0.009232</acceleration>
          <wrench>0.000669 -1e-06 1e-06 0 -0 0</wrench>
        </link>
        <link name='wrist3_Link'>
          <pose>7e-06 -0.215701 1.90845 1.57106 3.1e-05 1.2e-05</pose>
          <velocity>1e-06 -0 -0 -0 9e-06 9e-06</velocity>
          <acceleration>0.000279 0 -0 0.000105 0.464935 0.905761</acceleration>
          <wrench>0.000194 0 -0 0 -0 0</wrench>
        </link>
      </model>
      <model name='plastic_cup'>
        <pose>0.739693 -0.609481 0.97146 0.002729 -0.000545 1.51298</pose>
        <scale>1 1 1</scale>
        <link name='link'>
          <pose>0.739868 -0.609527 1.03646 0.002729 -0.000545 1.51298</pose>
          <velocity>0 0 0 0 -0 0</velocity>
          <acceleration>-0.035401 -0.162631 -0.018383 2.24171 -0.487306 0.048817</acceleration>
          <wrench>-0.002121 -0.009742 -0.001101 0 -0 0</wrench>
        </link>
      </model>
      <model name='plastic_cup_clone'>
        <pose>0.990275 -0.079926 0.97146 0.002735 -0.000544 1.51298</pose>
        <scale>1 1 1</scale>
        <link name='link'>
          <pose>0.990451 -0.079972 1.03646 0.002735 -0.000544 1.51298</pose>
          <velocity>0 0 0 0 -0 0</velocity>
          <acceleration>0.039705 0.146898 0.007269 -2.02502 0.546872 -0.045266</acceleration>
          <wrench>0.002378 0.008799 0.000435 0 -0 0</wrench>
        </link>
      </model>
      <model name='plastic_cup_clone_1'>
        <pose>1.06443 -0.315648 0.97146 0.002757 -0.000547 1.51298</pose>
        <scale>1 1 1</scale>
        <link name='link'>
          <pose>1.06461 -0.315694 1.03646 0.002757 -0.000547 1.51298</pose>
          <velocity>0 0 0 0 -0 0</velocity>
          <acceleration>0.029081 0.082485 0.001543 -1.13693 0.40059 -0.025811</acceleration>
          <wrench>0.001742 0.004941 9.2e-05 0 -0 0</wrench>
        </link>
      </model>
      <model name='plastic_cup_clone_2'>
        <pose>0.943408 0.490382 0.97146 0.002729 -0.000545 1.51298</pose>
        <scale>1 1 1</scale>
        <link name='link'>
          <pose>0.943583 0.490337 1.03646 0.002729 -0.000545 1.51298</pose>
          <velocity>0 0 0 0 -0 0</velocity>
          <acceleration>-0.032538 -0.162436 -0.019426 2.23902 -0.447827 0.048543</acceleration>
          <wrench>-0.001949 -0.00973 -0.001164 0 -0 0</wrench>
        </link>
      </model>
      <model name='plastic_cup_clone_3'>
        <pose>1.33797 0.168308 0.97146 0.002738 -0.000546 1.51298</pose>
        <scale>1 1 1</scale>
        <link name='link'>
          <pose>1.33814 0.168262 1.03646 0.002738 -0.000546 1.51298</pose>
          <velocity>0 0 0 0 -0 0</velocity>
          <acceleration>-0.035537 -0.162565 -0.018331 2.2408 -0.489177 0.048959</acceleration>
          <wrench>-0.002129 -0.009738 -0.001098 0 -0 0</wrench>
        </link>
      </model>
      <model name='table_marble'>
        <pose>1.03522 0.03566 0.648 0 -0 1.54087</pose>
        <scale>1 1 1</scale>
        <link name='link'>
          <pose>1.03522 0.03566 0.648 0 -0 1.54087</pose>
          <velocity>0 0 0 0 -0 0</velocity>
          <acceleration>0 0 0 0 -0 0</acceleration>
          <wrench>0 0 0 0 -0 0</wrench>
        </link>
      </model>
      <light name='sun'>
        <pose>0 0 10 0 -0 0</pose>
      </light>
    </state>
    <gui fullscreen='0'>
      <camera name='user_camera'>
        <pose>4.87805 1.50535 4.57172 0 0.711645 -3.13673</pose>
        <view_controller>orbit</view_controller>
        <projection_type>perspective</projection_type>
      </camera>
    </gui>
  </world>
</sdf>
